[2025-03-07T14:12:18.721+0000] {local_task_job_runner.py:123} INFO - ::group::Pre task execution logs
[2025-03-07T14:12:18.728+0000] {taskinstance.py:2614} INFO - Dependencies all met for dep_context=non-requeueable deps ti=<TaskInstance: climate_data_dlt_pipeline.extract_world_bank_data manual__2025-03-07T14:12:12.715072+00:00 [queued]>
[2025-03-07T14:12:18.732+0000] {taskinstance.py:2614} INFO - Dependencies all met for dep_context=requeueable deps ti=<TaskInstance: climate_data_dlt_pipeline.extract_world_bank_data manual__2025-03-07T14:12:12.715072+00:00 [queued]>
[2025-03-07T14:12:18.732+0000] {taskinstance.py:2867} INFO - Starting attempt 1 of 2
[2025-03-07T14:12:18.740+0000] {taskinstance.py:2890} INFO - Executing <Task(PythonOperator): extract_world_bank_data> on 2025-03-07 14:12:12.715072+00:00
[2025-03-07T14:12:18.747+0000] {standard_task_runner.py:72} INFO - Started process 8105 to run task
[2025-03-07T14:12:18.752+0000] {standard_task_runner.py:104} INFO - Running: ['airflow', 'tasks', 'run', 'climate_data_dlt_pipeline', 'extract_world_bank_data', 'manual__2025-03-07T14:12:12.715072+00:00', '--job-id', '24', '--raw', '--subdir', 'DAGS_FOLDER/dlt-airflow-dag.py', '--cfg-path', '/var/folders/55/x1yqz6851xj6j2f0smdhs4jh0000gn/T/tmpnznbqk1w']
[2025-03-07T14:12:18.754+0000] {standard_task_runner.py:105} INFO - Job 24: Subtask extract_world_bank_data
[2025-03-07T14:12:18.785+0000] {task_command.py:467} INFO - Running <TaskInstance: climate_data_dlt_pipeline.extract_world_bank_data manual__2025-03-07T14:12:12.715072+00:00 [running]> on host gabis-imac-pro.local
[2025-03-07T14:12:18.824+0000] {taskinstance.py:3134} INFO - Exporting env vars: AIRFLOW_CTX_DAG_OWNER='airflow' AIRFLOW_CTX_DAG_ID='climate_data_dlt_pipeline' AIRFLOW_CTX_TASK_ID='extract_world_bank_data' AIRFLOW_CTX_EXECUTION_DATE='2025-03-07T14:12:12.715072+00:00' AIRFLOW_CTX_TRY_NUMBER='1' AIRFLOW_CTX_DAG_RUN_ID='manual__2025-03-07T14:12:12.715072+00:00'
[2025-03-07T14:12:18.825+0000] {logging_mixin.py:190} INFO - Task instance is in running state
[2025-03-07T14:12:18.826+0000] {logging_mixin.py:190} INFO -  Previous state of the Task instance: queued
[2025-03-07T14:12:18.826+0000] {logging_mixin.py:190} INFO - Current task name:extract_world_bank_data state:running start_date:2025-03-07 14:12:18.728846+00:00
[2025-03-07T14:12:18.826+0000] {logging_mixin.py:190} INFO - Dag name:climate_data_dlt_pipeline and current dag run status:running
[2025-03-07T14:12:18.827+0000] {taskinstance.py:732} INFO - ::endgroup::
[2025-03-07T14:12:19.584+0000] {taskinstance.py:3313} ERROR - Task failed with exception
Traceback (most recent call last):
  File "/usr/local/anaconda3/envs/airflow_env/lib/python3.8/site-packages/dlt/pipeline/pipeline.py", line 471, in extract
    self._extract_source(
  File "/usr/local/anaconda3/envs/airflow_env/lib/python3.8/site-packages/dlt/pipeline/pipeline.py", line 1239, in _extract_source
    load_id = extract.extract(
  File "/usr/local/anaconda3/envs/airflow_env/lib/python3.8/site-packages/dlt/extract/extract.py", line 421, in extract
    self._extract_single_source(
  File "/usr/local/anaconda3/envs/airflow_env/lib/python3.8/site-packages/dlt/extract/extract.py", line 337, in _extract_single_source
    with PipeIterator.from_pipes(
  File "/usr/local/anaconda3/envs/airflow_env/lib/python3.8/site-packages/dlt/common/configuration/inject.py", line 247, in _wrap
    return f(*bound_args.args, **bound_args.kwargs)
  File "/usr/local/anaconda3/envs/airflow_env/lib/python3.8/site-packages/dlt/extract/pipe_iterator.py", line 145, in from_pipes
    _fork_pipeline(pipe)
  File "/usr/local/anaconda3/envs/airflow_env/lib/python3.8/site-packages/dlt/extract/pipe_iterator.py", line 137, in _fork_pipeline
    raise PipeGenInvalid(pipe.name, pipe.gen)
dlt.extract.exceptions.PipeGenInvalid: In processing pipe countries: A pipe generator element must be an Iterator (ie. list or generator function). Generator element is typically created from a `data` argument to pipeline.run or extract method. dlt will evaluate functions that were passed as data argument. If you passed a function the returned data type is not iterable.  Generator type is <class 'list'>.

The above exception was the direct cause of the following exception:

Traceback (most recent call last):
  File "/usr/local/anaconda3/envs/airflow_env/lib/python3.8/site-packages/airflow/models/taskinstance.py", line 768, in _execute_task
    result = _execute_callable(context=context, **execute_callable_kwargs)
  File "/usr/local/anaconda3/envs/airflow_env/lib/python3.8/site-packages/airflow/models/taskinstance.py", line 734, in _execute_callable
    return ExecutionCallableRunner(
  File "/usr/local/anaconda3/envs/airflow_env/lib/python3.8/site-packages/airflow/utils/operator_helpers.py", line 252, in run
    return self.func(*args, **kwargs)
  File "/usr/local/anaconda3/envs/airflow_env/lib/python3.8/site-packages/airflow/models/baseoperator.py", line 424, in wrapper
    return func(self, *args, **kwargs)
  File "/usr/local/anaconda3/envs/airflow_env/lib/python3.8/site-packages/airflow/operators/python.py", line 238, in execute
    return_value = self.execute_callable()
  File "/usr/local/anaconda3/envs/airflow_env/lib/python3.8/site-packages/airflow/operators/python.py", line 256, in execute_callable
    return runner.run(*self.op_args, **self.op_kwargs)
  File "/usr/local/anaconda3/envs/airflow_env/lib/python3.8/site-packages/airflow/utils/operator_helpers.py", line 252, in run
    return self.func(*args, **kwargs)
  File "/Users/gabi/codes/climate_trace/climate_data_pipeline/dags/dlt-airflow-dag.py", line 50, in extract_world_bank_data
    csv_path = run_world_bank_pipeline(year, WORLD_BANK_DIR)
  File "/Users/gabi/codes/climate_trace/climate_data_pipeline/scripts/dlt_extractor.py", line 172, in run_world_bank_pipeline
    load_info = pipeline.run(
  File "/usr/local/anaconda3/envs/airflow_env/lib/python3.8/site-packages/dlt/pipeline/pipeline.py", line 226, in _wrap
    step_info = f(self, *args, **kwargs)
  File "/usr/local/anaconda3/envs/airflow_env/lib/python3.8/site-packages/dlt/pipeline/pipeline.py", line 275, in _wrap
    return f(self, *args, **kwargs)
  File "/usr/local/anaconda3/envs/airflow_env/lib/python3.8/site-packages/dlt/pipeline/pipeline.py", line 735, in run
    self.extract(
  File "/usr/local/anaconda3/envs/airflow_env/lib/python3.8/site-packages/dlt/pipeline/pipeline.py", line 226, in _wrap
    step_info = f(self, *args, **kwargs)
  File "/usr/local/anaconda3/envs/airflow_env/lib/python3.8/site-packages/dlt/pipeline/pipeline.py", line 180, in _wrap
    rv = f(self, *args, **kwargs)
  File "/usr/local/anaconda3/envs/airflow_env/lib/python3.8/site-packages/dlt/pipeline/pipeline.py", line 166, in _wrap
    return f(self, *args, **kwargs)
  File "/usr/local/anaconda3/envs/airflow_env/lib/python3.8/site-packages/dlt/pipeline/pipeline.py", line 275, in _wrap
    return f(self, *args, **kwargs)
  File "/usr/local/anaconda3/envs/airflow_env/lib/python3.8/site-packages/dlt/pipeline/pipeline.py", line 492, in extract
    raise PipelineStepFailed(
dlt.pipeline.exceptions.PipelineStepFailed: Pipeline execution failed at stage extract when processing package 1741356739.1958668 with exception:

<class 'dlt.extract.exceptions.PipeGenInvalid'>
In processing pipe countries: A pipe generator element must be an Iterator (ie. list or generator function). Generator element is typically created from a `data` argument to pipeline.run or extract method. dlt will evaluate functions that were passed as data argument. If you passed a function the returned data type is not iterable.  Generator type is <class 'list'>.
[2025-03-07T14:12:19.590+0000] {logging_mixin.py:190} INFO - Task instance in failure state
[2025-03-07T14:12:19.591+0000] {logging_mixin.py:190} INFO - Task start:2025-03-07 14:12:18.728846+00:00 end:2025-03-07 14:12:19.590188+00:00 duration:0.861342
[2025-03-07T14:12:19.591+0000] {logging_mixin.py:190} INFO - Task:<Task(PythonOperator): extract_world_bank_data> dag:<DAG: climate_data_dlt_pipeline> dagrun:<DagRun climate_data_dlt_pipeline @ 2025-03-07 14:12:12.715072+00:00: manual__2025-03-07T14:12:12.715072+00:00, state:running, queued_at: 2025-03-07 14:12:12.725223+00:00. externally triggered: True>
[2025-03-07T14:12:19.591+0000] {logging_mixin.py:190} INFO - Failure caused by Pipeline execution failed at stage extract when processing package 1741356739.1958668 with exception:

<class 'dlt.extract.exceptions.PipeGenInvalid'>
In processing pipe countries: A pipe generator element must be an Iterator (ie. list or generator function). Generator element is typically created from a `data` argument to pipeline.run or extract method. dlt will evaluate functions that were passed as data argument. If you passed a function the returned data type is not iterable.  Generator type is <class 'list'>.
[2025-03-07T14:12:19.592+0000] {taskinstance.py:1226} INFO - Marking task as UP_FOR_RETRY. dag_id=climate_data_dlt_pipeline, task_id=extract_world_bank_data, run_id=manual__2025-03-07T14:12:12.715072+00:00, execution_date=20250307T141212, start_date=20250307T141218, end_date=20250307T141219
[2025-03-07T14:12:19.604+0000] {taskinstance.py:341} INFO - ::group::Post task execution logs
[2025-03-07T14:12:19.604+0000] {standard_task_runner.py:124} ERROR - Failed to execute job 24 for task extract_world_bank_data (Pipeline execution failed at stage extract when processing package 1741356739.1958668 with exception:

<class 'dlt.extract.exceptions.PipeGenInvalid'>
In processing pipe countries: A pipe generator element must be an Iterator (ie. list or generator function). Generator element is typically created from a `data` argument to pipeline.run or extract method. dlt will evaluate functions that were passed as data argument. If you passed a function the returned data type is not iterable.  Generator type is <class 'list'>.; 8105)
Traceback (most recent call last):
  File "/usr/local/anaconda3/envs/airflow_env/lib/python3.8/site-packages/dlt/pipeline/pipeline.py", line 471, in extract
    self._extract_source(
  File "/usr/local/anaconda3/envs/airflow_env/lib/python3.8/site-packages/dlt/pipeline/pipeline.py", line 1239, in _extract_source
    load_id = extract.extract(
  File "/usr/local/anaconda3/envs/airflow_env/lib/python3.8/site-packages/dlt/extract/extract.py", line 421, in extract
    self._extract_single_source(
  File "/usr/local/anaconda3/envs/airflow_env/lib/python3.8/site-packages/dlt/extract/extract.py", line 337, in _extract_single_source
    with PipeIterator.from_pipes(
  File "/usr/local/anaconda3/envs/airflow_env/lib/python3.8/site-packages/dlt/common/configuration/inject.py", line 247, in _wrap
    return f(*bound_args.args, **bound_args.kwargs)
  File "/usr/local/anaconda3/envs/airflow_env/lib/python3.8/site-packages/dlt/extract/pipe_iterator.py", line 145, in from_pipes
    _fork_pipeline(pipe)
  File "/usr/local/anaconda3/envs/airflow_env/lib/python3.8/site-packages/dlt/extract/pipe_iterator.py", line 137, in _fork_pipeline
    raise PipeGenInvalid(pipe.name, pipe.gen)
dlt.extract.exceptions.PipeGenInvalid: In processing pipe countries: A pipe generator element must be an Iterator (ie. list or generator function). Generator element is typically created from a `data` argument to pipeline.run or extract method. dlt will evaluate functions that were passed as data argument. If you passed a function the returned data type is not iterable.  Generator type is <class 'list'>.

The above exception was the direct cause of the following exception:

Traceback (most recent call last):
  File "/usr/local/anaconda3/envs/airflow_env/lib/python3.8/site-packages/airflow/task/task_runner/standard_task_runner.py", line 117, in _start_by_fork
    ret = args.func(args, dag=self.dag)
  File "/usr/local/anaconda3/envs/airflow_env/lib/python3.8/site-packages/airflow/cli/cli_config.py", line 49, in command
    return func(*args, **kwargs)
  File "/usr/local/anaconda3/envs/airflow_env/lib/python3.8/site-packages/airflow/utils/cli.py", line 116, in wrapper
    return f(*args, **kwargs)
  File "/usr/local/anaconda3/envs/airflow_env/lib/python3.8/site-packages/airflow/cli/commands/task_command.py", line 483, in task_run
    task_return_code = _run_task_by_selected_method(args, _dag, ti)
  File "/usr/local/anaconda3/envs/airflow_env/lib/python3.8/site-packages/airflow/cli/commands/task_command.py", line 256, in _run_task_by_selected_method
    return _run_raw_task(args, ti)
  File "/usr/local/anaconda3/envs/airflow_env/lib/python3.8/site-packages/airflow/cli/commands/task_command.py", line 341, in _run_raw_task
    return ti._run_raw_task(
  File "/usr/local/anaconda3/envs/airflow_env/lib/python3.8/site-packages/airflow/utils/session.py", line 97, in wrapper
    return func(*args, session=session, **kwargs)
  File "/usr/local/anaconda3/envs/airflow_env/lib/python3.8/site-packages/airflow/models/taskinstance.py", line 3006, in _run_raw_task
    return _run_raw_task(
  File "/usr/local/anaconda3/envs/airflow_env/lib/python3.8/site-packages/airflow/models/taskinstance.py", line 274, in _run_raw_task
    TaskInstance._execute_task_with_callbacks(
  File "/usr/local/anaconda3/envs/airflow_env/lib/python3.8/site-packages/airflow/models/taskinstance.py", line 3161, in _execute_task_with_callbacks
    result = self._execute_task(context, task_orig)
  File "/usr/local/anaconda3/envs/airflow_env/lib/python3.8/site-packages/airflow/models/taskinstance.py", line 3185, in _execute_task
    return _execute_task(self, context, task_orig)
  File "/usr/local/anaconda3/envs/airflow_env/lib/python3.8/site-packages/airflow/models/taskinstance.py", line 768, in _execute_task
    result = _execute_callable(context=context, **execute_callable_kwargs)
  File "/usr/local/anaconda3/envs/airflow_env/lib/python3.8/site-packages/airflow/models/taskinstance.py", line 734, in _execute_callable
    return ExecutionCallableRunner(
  File "/usr/local/anaconda3/envs/airflow_env/lib/python3.8/site-packages/airflow/utils/operator_helpers.py", line 252, in run
    return self.func(*args, **kwargs)
  File "/usr/local/anaconda3/envs/airflow_env/lib/python3.8/site-packages/airflow/models/baseoperator.py", line 424, in wrapper
    return func(self, *args, **kwargs)
  File "/usr/local/anaconda3/envs/airflow_env/lib/python3.8/site-packages/airflow/operators/python.py", line 238, in execute
    return_value = self.execute_callable()
  File "/usr/local/anaconda3/envs/airflow_env/lib/python3.8/site-packages/airflow/operators/python.py", line 256, in execute_callable
    return runner.run(*self.op_args, **self.op_kwargs)
  File "/usr/local/anaconda3/envs/airflow_env/lib/python3.8/site-packages/airflow/utils/operator_helpers.py", line 252, in run
    return self.func(*args, **kwargs)
  File "/Users/gabi/codes/climate_trace/climate_data_pipeline/dags/dlt-airflow-dag.py", line 50, in extract_world_bank_data
    csv_path = run_world_bank_pipeline(year, WORLD_BANK_DIR)
  File "/Users/gabi/codes/climate_trace/climate_data_pipeline/scripts/dlt_extractor.py", line 172, in run_world_bank_pipeline
    load_info = pipeline.run(
  File "/usr/local/anaconda3/envs/airflow_env/lib/python3.8/site-packages/dlt/pipeline/pipeline.py", line 226, in _wrap
    step_info = f(self, *args, **kwargs)
  File "/usr/local/anaconda3/envs/airflow_env/lib/python3.8/site-packages/dlt/pipeline/pipeline.py", line 275, in _wrap
    return f(self, *args, **kwargs)
  File "/usr/local/anaconda3/envs/airflow_env/lib/python3.8/site-packages/dlt/pipeline/pipeline.py", line 735, in run
    self.extract(
  File "/usr/local/anaconda3/envs/airflow_env/lib/python3.8/site-packages/dlt/pipeline/pipeline.py", line 226, in _wrap
    step_info = f(self, *args, **kwargs)
  File "/usr/local/anaconda3/envs/airflow_env/lib/python3.8/site-packages/dlt/pipeline/pipeline.py", line 180, in _wrap
    rv = f(self, *args, **kwargs)
  File "/usr/local/anaconda3/envs/airflow_env/lib/python3.8/site-packages/dlt/pipeline/pipeline.py", line 166, in _wrap
    return f(self, *args, **kwargs)
  File "/usr/local/anaconda3/envs/airflow_env/lib/python3.8/site-packages/dlt/pipeline/pipeline.py", line 275, in _wrap
    return f(self, *args, **kwargs)
  File "/usr/local/anaconda3/envs/airflow_env/lib/python3.8/site-packages/dlt/pipeline/pipeline.py", line 492, in extract
    raise PipelineStepFailed(
dlt.pipeline.exceptions.PipelineStepFailed: Pipeline execution failed at stage extract when processing package 1741356739.1958668 with exception:

<class 'dlt.extract.exceptions.PipeGenInvalid'>
In processing pipe countries: A pipe generator element must be an Iterator (ie. list or generator function). Generator element is typically created from a `data` argument to pipeline.run or extract method. dlt will evaluate functions that were passed as data argument. If you passed a function the returned data type is not iterable.  Generator type is <class 'list'>.
[2025-03-07T14:12:19.644+0000] {local_task_job_runner.py:266} INFO - Task exited with return code 1
[2025-03-07T14:12:19.656+0000] {taskinstance.py:3901} INFO - 0 downstream tasks scheduled from follow-on schedule check
[2025-03-07T14:12:19.657+0000] {local_task_job_runner.py:245} INFO - ::endgroup::
