[2025-03-07T16:32:09.443+0100] {local_task_job_runner.py:123} INFO - ::group::Pre task execution logs
[2025-03-07T16:32:09.450+0100] {taskinstance.py:2614} INFO - Dependencies all met for dep_context=non-requeueable deps ti=<TaskInstance: climate_data_spark_processing.wait_for_extraction manual__2025-03-07T15:32:05.087813+00:00 [queued]>
[2025-03-07T16:32:09.454+0100] {taskinstance.py:2614} INFO - Dependencies all met for dep_context=requeueable deps ti=<TaskInstance: climate_data_spark_processing.wait_for_extraction manual__2025-03-07T15:32:05.087813+00:00 [queued]>
[2025-03-07T16:32:09.454+0100] {taskinstance.py:2867} INFO - Starting attempt 1 of 2
[2025-03-07T16:32:09.461+0100] {taskinstance.py:2890} INFO - Executing <Task(ExternalTaskSensor): wait_for_extraction> on 2025-03-07 15:32:05.087813+00:00
[2025-03-07T16:32:09.469+0100] {standard_task_runner.py:72} INFO - Started process 16489 to run task
[2025-03-07T16:32:09.474+0100] {standard_task_runner.py:104} INFO - Running: ['airflow', 'tasks', 'run', 'climate_data_spark_processing', 'wait_for_extraction', 'manual__2025-03-07T15:32:05.087813+00:00', '--job-id', '79', '--raw', '--subdir', 'DAGS_FOLDER/spark-processing-dag.py', '--cfg-path', '/var/folders/55/x1yqz6851xj6j2f0smdhs4jh0000gn/T/tmpi8ndnvx0']
[2025-03-07T16:32:09.476+0100] {standard_task_runner.py:105} INFO - Job 79: Subtask wait_for_extraction
[2025-03-07T16:32:09.513+0100] {task_command.py:467} INFO - Running <TaskInstance: climate_data_spark_processing.wait_for_extraction manual__2025-03-07T15:32:05.087813+00:00 [running]> on host gabis-imac-pro.local
[2025-03-07T16:32:09.548+0100] {taskinstance.py:3134} INFO - Exporting env vars: AIRFLOW_CTX_DAG_OWNER='zoomcamp' AIRFLOW_CTX_DAG_ID='climate_data_spark_processing' AIRFLOW_CTX_TASK_ID='wait_for_extraction' AIRFLOW_CTX_EXECUTION_DATE='2025-03-07T15:32:05.087813+00:00' AIRFLOW_CTX_TRY_NUMBER='1' AIRFLOW_CTX_DAG_RUN_ID='manual__2025-03-07T15:32:05.087813+00:00'
[2025-03-07T16:32:09.550+0100] {logging_mixin.py:190} INFO - Task instance is in running state
[2025-03-07T16:32:09.550+0100] {logging_mixin.py:190} INFO -  Previous state of the Task instance: queued
[2025-03-07T16:32:09.550+0100] {logging_mixin.py:190} INFO - Current task name:wait_for_extraction state:running start_date:2025-03-07 15:32:09.450971+00:00
[2025-03-07T16:32:09.551+0100] {logging_mixin.py:190} INFO - Dag name:climate_data_spark_processing and current dag run status:running
[2025-03-07T16:32:09.551+0100] {taskinstance.py:732} INFO - ::endgroup::
[2025-03-07T16:32:09.552+0100] {baseoperator.py:423} WARNING - ExternalTaskSensor.execute cannot be called outside TaskInstance!
[2025-03-07T16:32:09.552+0100] {external_task.py:274} INFO - Poking for DAG 'climate_data_pipeline' on 2025-03-07T15:32:05.087813+00:00 ... 
[2025-03-07T16:32:09.557+0100] {logging_mixin.py:190} WARNING - /usr/local/anaconda3/envs/airflow_env/lib/python3.8/site-packages/airflow/utils/session.py:97 DeprecationWarning: This method is deprecated and will be removed in future.
[2025-03-07T16:33:09.557+0100] {external_task.py:274} INFO - Poking for DAG 'climate_data_pipeline' on 2025-03-07T15:32:05.087813+00:00 ... 
[2025-03-07T16:34:09.558+0100] {external_task.py:274} INFO - Poking for DAG 'climate_data_pipeline' on 2025-03-07T15:32:05.087813+00:00 ... 
[2025-03-07T16:35:09.560+0100] {external_task.py:274} INFO - Poking for DAG 'climate_data_pipeline' on 2025-03-07T15:32:05.087813+00:00 ... 
[2025-03-07T16:36:09.561+0100] {external_task.py:274} INFO - Poking for DAG 'climate_data_pipeline' on 2025-03-07T15:32:05.087813+00:00 ... 
[2025-03-07T16:37:09.562+0100] {external_task.py:274} INFO - Poking for DAG 'climate_data_pipeline' on 2025-03-07T15:32:05.087813+00:00 ... 
[2025-03-07T16:38:09.563+0100] {external_task.py:274} INFO - Poking for DAG 'climate_data_pipeline' on 2025-03-07T15:32:05.087813+00:00 ... 
[2025-03-07T16:38:54.657+0100] {local_task_job_runner.py:245} INFO - ::endgroup::
[2025-03-07T16:38:54.665+0100] {process_utils.py:132} INFO - Sending 15 to group 16489. PIDs of all processes in the group: [16489]
[2025-03-07T16:38:54.666+0100] {process_utils.py:87} INFO - Sending the signal 15 to group 16489
[2025-03-07T16:38:54.666+0100] {taskinstance.py:3094} ERROR - Received SIGTERM. Terminating subprocesses.
[2025-03-07T16:38:54.671+0100] {taskinstance.py:3095} ERROR - Stacktrace: 
  File "/usr/local/anaconda3/envs/airflow_env/bin/airflow", line 8, in <module>
    sys.exit(main())
  File "/usr/local/anaconda3/envs/airflow_env/lib/python3.8/site-packages/airflow/__main__.py", line 62, in main
    args.func(args)
  File "/usr/local/anaconda3/envs/airflow_env/lib/python3.8/site-packages/airflow/cli/cli_config.py", line 49, in command
    return func(*args, **kwargs)
  File "/usr/local/anaconda3/envs/airflow_env/lib/python3.8/site-packages/airflow/utils/cli.py", line 116, in wrapper
    return f(*args, **kwargs)
  File "/usr/local/anaconda3/envs/airflow_env/lib/python3.8/site-packages/airflow/cli/commands/task_command.py", line 483, in task_run
    task_return_code = _run_task_by_selected_method(args, _dag, ti)
  File "/usr/local/anaconda3/envs/airflow_env/lib/python3.8/site-packages/airflow/cli/commands/task_command.py", line 254, in _run_task_by_selected_method
    return _run_task_by_local_task_job(args, ti)
  File "/usr/local/anaconda3/envs/airflow_env/lib/python3.8/site-packages/airflow/cli/commands/task_command.py", line 322, in _run_task_by_local_task_job
    ret = run_job(job=job_runner.job, execute_callable=job_runner._execute)
  File "/usr/local/anaconda3/envs/airflow_env/lib/python3.8/site-packages/airflow/utils/session.py", line 97, in wrapper
    return func(*args, session=session, **kwargs)
  File "/usr/local/anaconda3/envs/airflow_env/lib/python3.8/site-packages/airflow/jobs/job.py", line 421, in run_job
    return execute_job(job, execute_callable=execute_callable)
  File "/usr/local/anaconda3/envs/airflow_env/lib/python3.8/site-packages/airflow/jobs/job.py", line 450, in execute_job
    ret = execute_callable()
  File "/usr/local/anaconda3/envs/airflow_env/lib/python3.8/site-packages/airflow/jobs/local_task_job_runner.py", line 171, in _execute
    self.task_runner.start()
  File "/usr/local/anaconda3/envs/airflow_env/lib/python3.8/site-packages/airflow/task/task_runner/standard_task_runner.py", line 55, in start
    self.process = self._start_by_fork()
  File "/usr/local/anaconda3/envs/airflow_env/lib/python3.8/site-packages/airflow/task/task_runner/standard_task_runner.py", line 117, in _start_by_fork
    ret = args.func(args, dag=self.dag)
  File "/usr/local/anaconda3/envs/airflow_env/lib/python3.8/site-packages/airflow/cli/cli_config.py", line 49, in command
    return func(*args, **kwargs)
  File "/usr/local/anaconda3/envs/airflow_env/lib/python3.8/site-packages/airflow/utils/cli.py", line 116, in wrapper
    return f(*args, **kwargs)
  File "/usr/local/anaconda3/envs/airflow_env/lib/python3.8/site-packages/airflow/cli/commands/task_command.py", line 483, in task_run
    task_return_code = _run_task_by_selected_method(args, _dag, ti)
  File "/usr/local/anaconda3/envs/airflow_env/lib/python3.8/site-packages/airflow/cli/commands/task_command.py", line 256, in _run_task_by_selected_method
    return _run_raw_task(args, ti)
  File "/usr/local/anaconda3/envs/airflow_env/lib/python3.8/site-packages/airflow/cli/commands/task_command.py", line 341, in _run_raw_task
    return ti._run_raw_task(
  File "/usr/local/anaconda3/envs/airflow_env/lib/python3.8/site-packages/airflow/utils/session.py", line 97, in wrapper
    return func(*args, session=session, **kwargs)
  File "/usr/local/anaconda3/envs/airflow_env/lib/python3.8/site-packages/airflow/models/taskinstance.py", line 3006, in _run_raw_task
    return _run_raw_task(
  File "/usr/local/anaconda3/envs/airflow_env/lib/python3.8/site-packages/airflow/models/taskinstance.py", line 274, in _run_raw_task
    TaskInstance._execute_task_with_callbacks(
  File "/usr/local/anaconda3/envs/airflow_env/lib/python3.8/site-packages/airflow/models/taskinstance.py", line 3161, in _execute_task_with_callbacks
    result = self._execute_task(context, task_orig)
  File "/usr/local/anaconda3/envs/airflow_env/lib/python3.8/site-packages/airflow/models/taskinstance.py", line 3185, in _execute_task
    return _execute_task(self, context, task_orig)
  File "/usr/local/anaconda3/envs/airflow_env/lib/python3.8/site-packages/airflow/models/taskinstance.py", line 768, in _execute_task
    result = _execute_callable(context=context, **execute_callable_kwargs)
  File "/usr/local/anaconda3/envs/airflow_env/lib/python3.8/site-packages/airflow/models/taskinstance.py", line 734, in _execute_callable
    return ExecutionCallableRunner(
  File "/usr/local/anaconda3/envs/airflow_env/lib/python3.8/site-packages/airflow/utils/operator_helpers.py", line 252, in run
    return self.func(*args, **kwargs)
  File "/usr/local/anaconda3/envs/airflow_env/lib/python3.8/site-packages/airflow/models/baseoperator.py", line 424, in wrapper
    return func(self, *args, **kwargs)
  File "/usr/local/anaconda3/envs/airflow_env/lib/python3.8/site-packages/airflow/sensors/external_task.py", line 348, in execute
    super().execute(context)
  File "/usr/local/anaconda3/envs/airflow_env/lib/python3.8/site-packages/airflow/models/baseoperator.py", line 424, in wrapper
    return func(self, *args, **kwargs)
  File "/usr/local/anaconda3/envs/airflow_env/lib/python3.8/site-packages/airflow/sensors/base.py", line 337, in execute
    time.sleep(self._get_next_poke_interval(started_at, run_duration, poke_count))
  File "/usr/local/anaconda3/envs/airflow_env/lib/python3.8/site-packages/airflow/models/taskinstance.py", line 3095, in signal_handler
    self.log.error("Stacktrace: \n%s", "".join(traceback.format_stack()))

[2025-03-07T16:38:54.675+0100] {taskinstance.py:3313} ERROR - Task failed with exception
Traceback (most recent call last):
  File "/usr/local/anaconda3/envs/airflow_env/lib/python3.8/site-packages/airflow/models/taskinstance.py", line 768, in _execute_task
    result = _execute_callable(context=context, **execute_callable_kwargs)
  File "/usr/local/anaconda3/envs/airflow_env/lib/python3.8/site-packages/airflow/models/taskinstance.py", line 734, in _execute_callable
    return ExecutionCallableRunner(
  File "/usr/local/anaconda3/envs/airflow_env/lib/python3.8/site-packages/airflow/utils/operator_helpers.py", line 252, in run
    return self.func(*args, **kwargs)
  File "/usr/local/anaconda3/envs/airflow_env/lib/python3.8/site-packages/airflow/models/baseoperator.py", line 424, in wrapper
    return func(self, *args, **kwargs)
  File "/usr/local/anaconda3/envs/airflow_env/lib/python3.8/site-packages/airflow/sensors/external_task.py", line 348, in execute
    super().execute(context)
  File "/usr/local/anaconda3/envs/airflow_env/lib/python3.8/site-packages/airflow/models/baseoperator.py", line 424, in wrapper
    return func(self, *args, **kwargs)
  File "/usr/local/anaconda3/envs/airflow_env/lib/python3.8/site-packages/airflow/sensors/base.py", line 337, in execute
    time.sleep(self._get_next_poke_interval(started_at, run_duration, poke_count))
  File "/usr/local/anaconda3/envs/airflow_env/lib/python3.8/site-packages/airflow/models/taskinstance.py", line 3097, in signal_handler
    raise AirflowTaskTerminated("Task received SIGTERM signal")
airflow.exceptions.AirflowTaskTerminated: Task received SIGTERM signal
[2025-03-07T16:38:54.679+0100] {logging_mixin.py:190} INFO - Task instance in failure state
[2025-03-07T16:38:54.679+0100] {logging_mixin.py:190} INFO - Task start:2025-03-07 15:32:09.450971+00:00 end:2025-03-07 15:38:54.678720+00:00 duration:405.227749
[2025-03-07T16:38:54.680+0100] {logging_mixin.py:190} INFO - Task:<Task(ExternalTaskSensor): wait_for_extraction> dag:<DAG: climate_data_spark_processing> dagrun:<DagRun climate_data_spark_processing @ 2025-03-07 15:32:05.087813+00:00: manual__2025-03-07T15:32:05.087813+00:00, state:running, queued_at: 2025-03-07 15:32:05.454918+00:00. externally triggered: True>
[2025-03-07T16:38:54.680+0100] {logging_mixin.py:190} INFO - Failure caused by Task received SIGTERM signal
[2025-03-07T16:38:54.680+0100] {taskinstance.py:1226} INFO - Marking task as UP_FOR_RETRY. dag_id=climate_data_spark_processing, task_id=wait_for_extraction, run_id=manual__2025-03-07T15:32:05.087813+00:00, execution_date=20250307T153205, start_date=20250307T153209, end_date=20250307T153854
[2025-03-07T16:38:54.694+0100] {taskinstance.py:341} INFO - ::group::Post task execution logs
[2025-03-07T16:38:54.725+0100] {process_utils.py:80} INFO - Process psutil.Process(pid=16489, status='terminated', exitcode=2, started='16:32:09') (16489) terminated with exit code 2
[2025-03-07T16:38:58.953+0100] {local_task_job_runner.py:123} INFO - ::group::Pre task execution logs
[2025-03-07T16:38:58.960+0100] {taskinstance.py:2604} INFO - Dependencies not met for <TaskInstance: climate_data_spark_processing.wait_for_extraction manual__2025-03-07T15:32:05.087813+00:00 [up_for_retry]>, dependency 'Not In Retry Period' FAILED: Task is not ready for retry yet but will be retried automatically. Current date is 2025-03-07T15:38:58.960779+00:00 and task will be retried at 2025-03-07T15:43:54.678720+00:00.
[2025-03-07T16:38:58.961+0100] {local_task_job_runner.py:166} INFO - Task is not able to be run
