[2025-03-07T14:01:21.525+0000] {local_task_job_runner.py:123} INFO - ::group::Pre task execution logs
[2025-03-07T14:01:21.533+0000] {taskinstance.py:2614} INFO - Dependencies all met for dep_context=non-requeueable deps ti=<TaskInstance: climate_data_dlt_pipeline.extract_climate_trace_data scheduled__2025-03-06T00:00:00+00:00 [queued]>
[2025-03-07T14:01:21.536+0000] {taskinstance.py:2614} INFO - Dependencies all met for dep_context=requeueable deps ti=<TaskInstance: climate_data_dlt_pipeline.extract_climate_trace_data scheduled__2025-03-06T00:00:00+00:00 [queued]>
[2025-03-07T14:01:21.537+0000] {taskinstance.py:2867} INFO - Starting attempt 1 of 2
[2025-03-07T14:01:21.544+0000] {taskinstance.py:2890} INFO - Executing <Task(PythonOperator): extract_climate_trace_data> on 2025-03-06 00:00:00+00:00
[2025-03-07T14:01:21.551+0000] {standard_task_runner.py:72} INFO - Started process 6947 to run task
[2025-03-07T14:01:21.557+0000] {standard_task_runner.py:104} INFO - Running: ['airflow', 'tasks', 'run', 'climate_data_dlt_pipeline', 'extract_climate_trace_data', 'scheduled__2025-03-06T00:00:00+00:00', '--job-id', '16', '--raw', '--subdir', 'DAGS_FOLDER/dlt-airflow-dag.py', '--cfg-path', '/var/folders/55/x1yqz6851xj6j2f0smdhs4jh0000gn/T/tmp720pyjcg']
[2025-03-07T14:01:21.558+0000] {standard_task_runner.py:105} INFO - Job 16: Subtask extract_climate_trace_data
[2025-03-07T14:01:21.591+0000] {task_command.py:467} INFO - Running <TaskInstance: climate_data_dlt_pipeline.extract_climate_trace_data scheduled__2025-03-06T00:00:00+00:00 [running]> on host gabis-imac-pro.local
[2025-03-07T14:01:21.631+0000] {taskinstance.py:3134} INFO - Exporting env vars: AIRFLOW_CTX_DAG_OWNER='airflow' AIRFLOW_CTX_DAG_ID='climate_data_dlt_pipeline' AIRFLOW_CTX_TASK_ID='extract_climate_trace_data' AIRFLOW_CTX_EXECUTION_DATE='2025-03-06T00:00:00+00:00' AIRFLOW_CTX_TRY_NUMBER='1' AIRFLOW_CTX_DAG_RUN_ID='scheduled__2025-03-06T00:00:00+00:00'
[2025-03-07T14:01:21.632+0000] {logging_mixin.py:190} INFO - Task instance is in running state
[2025-03-07T14:01:21.632+0000] {logging_mixin.py:190} INFO -  Previous state of the Task instance: queued
[2025-03-07T14:01:21.632+0000] {logging_mixin.py:190} INFO - Current task name:extract_climate_trace_data state:running start_date:2025-03-07 14:01:21.533219+00:00
[2025-03-07T14:01:21.633+0000] {logging_mixin.py:190} INFO - Dag name:climate_data_dlt_pipeline and current dag run status:running
[2025-03-07T14:01:21.633+0000] {taskinstance.py:732} INFO - ::endgroup::
[2025-03-07T14:01:21.831+0000] {taskinstance.py:3313} ERROR - Task failed with exception
Traceback (most recent call last):
  File "/usr/local/anaconda3/envs/airflow_env/lib/python3.8/site-packages/airflow/models/taskinstance.py", line 768, in _execute_task
    result = _execute_callable(context=context, **execute_callable_kwargs)
  File "/usr/local/anaconda3/envs/airflow_env/lib/python3.8/site-packages/airflow/models/taskinstance.py", line 734, in _execute_callable
    return ExecutionCallableRunner(
  File "/usr/local/anaconda3/envs/airflow_env/lib/python3.8/site-packages/airflow/utils/operator_helpers.py", line 252, in run
    return self.func(*args, **kwargs)
  File "/usr/local/anaconda3/envs/airflow_env/lib/python3.8/site-packages/airflow/models/baseoperator.py", line 424, in wrapper
    return func(self, *args, **kwargs)
  File "/usr/local/anaconda3/envs/airflow_env/lib/python3.8/site-packages/airflow/operators/python.py", line 238, in execute
    return_value = self.execute_callable()
  File "/usr/local/anaconda3/envs/airflow_env/lib/python3.8/site-packages/airflow/operators/python.py", line 256, in execute_callable
    return runner.run(*self.op_args, **self.op_kwargs)
  File "/usr/local/anaconda3/envs/airflow_env/lib/python3.8/site-packages/airflow/utils/operator_helpers.py", line 252, in run
    return self.func(*args, **kwargs)
  File "/Users/gabi/codes/climate_trace/climate_data_pipeline/dags/dlt-airflow-dag.py", line 56, in extract_climate_trace_data
    csv_path = run_climate_trace_pipeline(year, CLIMATE_TRACE_DIR)
  File "/Users/gabi/codes/climate_trace/climate_data_pipeline/scripts/dlt_extractor.py", line 190, in run_climate_trace_pipeline
    load_info = pipeline.run(
  File "/usr/local/anaconda3/envs/airflow_env/lib/python3.8/site-packages/dlt/pipeline/pipeline.py", line 226, in _wrap
    step_info = f(self, *args, **kwargs)
  File "/usr/local/anaconda3/envs/airflow_env/lib/python3.8/site-packages/dlt/pipeline/pipeline.py", line 275, in _wrap
    return f(self, *args, **kwargs)
TypeError: run() got an unexpected keyword argument 'destination_path'
[2025-03-07T14:01:21.841+0000] {logging_mixin.py:190} INFO - Task instance in failure state
[2025-03-07T14:01:21.842+0000] {logging_mixin.py:190} INFO - Task start:2025-03-07 14:01:21.533219+00:00 end:2025-03-07 14:01:21.841292+00:00 duration:0.308073
[2025-03-07T14:01:21.842+0000] {logging_mixin.py:190} INFO - Task:<Task(PythonOperator): extract_climate_trace_data> dag:<DAG: climate_data_dlt_pipeline> dagrun:<DagRun climate_data_dlt_pipeline @ 2025-03-06 00:00:00+00:00: scheduled__2025-03-06T00:00:00+00:00, state:running, queued_at: 2025-03-07 14:01:14.083246+00:00. externally triggered: False>
[2025-03-07T14:01:21.842+0000] {logging_mixin.py:190} INFO - Failure caused by run() got an unexpected keyword argument 'destination_path'
[2025-03-07T14:01:21.843+0000] {taskinstance.py:1226} INFO - Marking task as UP_FOR_RETRY. dag_id=climate_data_dlt_pipeline, task_id=extract_climate_trace_data, run_id=scheduled__2025-03-06T00:00:00+00:00, execution_date=20250306T000000, start_date=20250307T140121, end_date=20250307T140121
[2025-03-07T14:01:21.857+0000] {taskinstance.py:341} INFO - ::group::Post task execution logs
[2025-03-07T14:01:21.858+0000] {standard_task_runner.py:124} ERROR - Failed to execute job 16 for task extract_climate_trace_data (run() got an unexpected keyword argument 'destination_path'; 6947)
Traceback (most recent call last):
  File "/usr/local/anaconda3/envs/airflow_env/lib/python3.8/site-packages/airflow/task/task_runner/standard_task_runner.py", line 117, in _start_by_fork
    ret = args.func(args, dag=self.dag)
  File "/usr/local/anaconda3/envs/airflow_env/lib/python3.8/site-packages/airflow/cli/cli_config.py", line 49, in command
    return func(*args, **kwargs)
  File "/usr/local/anaconda3/envs/airflow_env/lib/python3.8/site-packages/airflow/utils/cli.py", line 116, in wrapper
    return f(*args, **kwargs)
  File "/usr/local/anaconda3/envs/airflow_env/lib/python3.8/site-packages/airflow/cli/commands/task_command.py", line 483, in task_run
    task_return_code = _run_task_by_selected_method(args, _dag, ti)
  File "/usr/local/anaconda3/envs/airflow_env/lib/python3.8/site-packages/airflow/cli/commands/task_command.py", line 256, in _run_task_by_selected_method
    return _run_raw_task(args, ti)
  File "/usr/local/anaconda3/envs/airflow_env/lib/python3.8/site-packages/airflow/cli/commands/task_command.py", line 341, in _run_raw_task
    return ti._run_raw_task(
  File "/usr/local/anaconda3/envs/airflow_env/lib/python3.8/site-packages/airflow/utils/session.py", line 97, in wrapper
    return func(*args, session=session, **kwargs)
  File "/usr/local/anaconda3/envs/airflow_env/lib/python3.8/site-packages/airflow/models/taskinstance.py", line 3006, in _run_raw_task
    return _run_raw_task(
  File "/usr/local/anaconda3/envs/airflow_env/lib/python3.8/site-packages/airflow/models/taskinstance.py", line 274, in _run_raw_task
    TaskInstance._execute_task_with_callbacks(
  File "/usr/local/anaconda3/envs/airflow_env/lib/python3.8/site-packages/airflow/models/taskinstance.py", line 3161, in _execute_task_with_callbacks
    result = self._execute_task(context, task_orig)
  File "/usr/local/anaconda3/envs/airflow_env/lib/python3.8/site-packages/airflow/models/taskinstance.py", line 3185, in _execute_task
    return _execute_task(self, context, task_orig)
  File "/usr/local/anaconda3/envs/airflow_env/lib/python3.8/site-packages/airflow/models/taskinstance.py", line 768, in _execute_task
    result = _execute_callable(context=context, **execute_callable_kwargs)
  File "/usr/local/anaconda3/envs/airflow_env/lib/python3.8/site-packages/airflow/models/taskinstance.py", line 734, in _execute_callable
    return ExecutionCallableRunner(
  File "/usr/local/anaconda3/envs/airflow_env/lib/python3.8/site-packages/airflow/utils/operator_helpers.py", line 252, in run
    return self.func(*args, **kwargs)
  File "/usr/local/anaconda3/envs/airflow_env/lib/python3.8/site-packages/airflow/models/baseoperator.py", line 424, in wrapper
    return func(self, *args, **kwargs)
  File "/usr/local/anaconda3/envs/airflow_env/lib/python3.8/site-packages/airflow/operators/python.py", line 238, in execute
    return_value = self.execute_callable()
  File "/usr/local/anaconda3/envs/airflow_env/lib/python3.8/site-packages/airflow/operators/python.py", line 256, in execute_callable
    return runner.run(*self.op_args, **self.op_kwargs)
  File "/usr/local/anaconda3/envs/airflow_env/lib/python3.8/site-packages/airflow/utils/operator_helpers.py", line 252, in run
    return self.func(*args, **kwargs)
  File "/Users/gabi/codes/climate_trace/climate_data_pipeline/dags/dlt-airflow-dag.py", line 56, in extract_climate_trace_data
    csv_path = run_climate_trace_pipeline(year, CLIMATE_TRACE_DIR)
  File "/Users/gabi/codes/climate_trace/climate_data_pipeline/scripts/dlt_extractor.py", line 190, in run_climate_trace_pipeline
    load_info = pipeline.run(
  File "/usr/local/anaconda3/envs/airflow_env/lib/python3.8/site-packages/dlt/pipeline/pipeline.py", line 226, in _wrap
    step_info = f(self, *args, **kwargs)
  File "/usr/local/anaconda3/envs/airflow_env/lib/python3.8/site-packages/dlt/pipeline/pipeline.py", line 275, in _wrap
    return f(self, *args, **kwargs)
TypeError: run() got an unexpected keyword argument 'destination_path'
[2025-03-07T14:01:21.871+0000] {local_task_job_runner.py:266} INFO - Task exited with return code 1
[2025-03-07T14:01:21.883+0000] {taskinstance.py:3901} INFO - 0 downstream tasks scheduled from follow-on schedule check
[2025-03-07T14:01:21.883+0000] {local_task_job_runner.py:245} INFO - ::endgroup::
