[2025-03-07T14:06:34.722+0000] {local_task_job_runner.py:123} INFO - ::group::Pre task execution logs
[2025-03-07T14:06:34.729+0000] {taskinstance.py:2614} INFO - Dependencies all met for dep_context=non-requeueable deps ti=<TaskInstance: climate_data_dlt_pipeline.extract_world_bank_data manual__2025-03-07T14:06:29.267614+00:00 [queued]>
[2025-03-07T14:06:34.733+0000] {taskinstance.py:2614} INFO - Dependencies all met for dep_context=requeueable deps ti=<TaskInstance: climate_data_dlt_pipeline.extract_world_bank_data manual__2025-03-07T14:06:29.267614+00:00 [queued]>
[2025-03-07T14:06:34.733+0000] {taskinstance.py:2867} INFO - Starting attempt 1 of 2
[2025-03-07T14:06:34.741+0000] {taskinstance.py:2890} INFO - Executing <Task(PythonOperator): extract_world_bank_data> on 2025-03-07 14:06:29.267614+00:00
[2025-03-07T14:06:34.748+0000] {standard_task_runner.py:72} INFO - Started process 7490 to run task
[2025-03-07T14:06:34.754+0000] {standard_task_runner.py:104} INFO - Running: ['airflow', 'tasks', 'run', 'climate_data_dlt_pipeline', 'extract_world_bank_data', 'manual__2025-03-07T14:06:29.267614+00:00', '--job-id', '17', '--raw', '--subdir', 'DAGS_FOLDER/dlt-airflow-dag.py', '--cfg-path', '/var/folders/55/x1yqz6851xj6j2f0smdhs4jh0000gn/T/tmpjef5z9cr']
[2025-03-07T14:06:34.755+0000] {standard_task_runner.py:105} INFO - Job 17: Subtask extract_world_bank_data
[2025-03-07T14:06:34.791+0000] {task_command.py:467} INFO - Running <TaskInstance: climate_data_dlt_pipeline.extract_world_bank_data manual__2025-03-07T14:06:29.267614+00:00 [running]> on host gabis-imac-pro.local
[2025-03-07T14:06:34.831+0000] {taskinstance.py:3134} INFO - Exporting env vars: AIRFLOW_CTX_DAG_OWNER='airflow' AIRFLOW_CTX_DAG_ID='climate_data_dlt_pipeline' AIRFLOW_CTX_TASK_ID='extract_world_bank_data' AIRFLOW_CTX_EXECUTION_DATE='2025-03-07T14:06:29.267614+00:00' AIRFLOW_CTX_TRY_NUMBER='1' AIRFLOW_CTX_DAG_RUN_ID='manual__2025-03-07T14:06:29.267614+00:00'
[2025-03-07T14:06:34.832+0000] {logging_mixin.py:190} INFO - Task instance is in running state
[2025-03-07T14:06:34.832+0000] {logging_mixin.py:190} INFO -  Previous state of the Task instance: queued
[2025-03-07T14:06:34.833+0000] {logging_mixin.py:190} INFO - Current task name:extract_world_bank_data state:running start_date:2025-03-07 14:06:34.730044+00:00
[2025-03-07T14:06:34.833+0000] {logging_mixin.py:190} INFO - Dag name:climate_data_dlt_pipeline and current dag run status:running
[2025-03-07T14:06:34.833+0000] {taskinstance.py:732} INFO - ::endgroup::
[2025-03-07T14:06:34.901+0000] {taskinstance.py:3313} ERROR - Task failed with exception
Traceback (most recent call last):
  File "/usr/local/anaconda3/envs/airflow_env/lib/python3.8/site-packages/airflow/models/taskinstance.py", line 768, in _execute_task
    result = _execute_callable(context=context, **execute_callable_kwargs)
  File "/usr/local/anaconda3/envs/airflow_env/lib/python3.8/site-packages/airflow/models/taskinstance.py", line 734, in _execute_callable
    return ExecutionCallableRunner(
  File "/usr/local/anaconda3/envs/airflow_env/lib/python3.8/site-packages/airflow/utils/operator_helpers.py", line 252, in run
    return self.func(*args, **kwargs)
  File "/usr/local/anaconda3/envs/airflow_env/lib/python3.8/site-packages/airflow/models/baseoperator.py", line 424, in wrapper
    return func(self, *args, **kwargs)
  File "/usr/local/anaconda3/envs/airflow_env/lib/python3.8/site-packages/airflow/operators/python.py", line 238, in execute
    return_value = self.execute_callable()
  File "/usr/local/anaconda3/envs/airflow_env/lib/python3.8/site-packages/airflow/operators/python.py", line 256, in execute_callable
    return runner.run(*self.op_args, **self.op_kwargs)
  File "/usr/local/anaconda3/envs/airflow_env/lib/python3.8/site-packages/airflow/utils/operator_helpers.py", line 252, in run
    return self.func(*args, **kwargs)
  File "/Users/gabi/codes/climate_trace/climate_data_pipeline/dags/dlt-airflow-dag.py", line 50, in extract_world_bank_data
    csv_path = run_world_bank_pipeline(year, WORLD_BANK_DIR)
  File "/Users/gabi/codes/climate_trace/climate_data_pipeline/scripts/dlt_extractor.py", line 155, in run_world_bank_pipeline
    pipeline = dlt.pipeline(
  File "/usr/local/anaconda3/envs/airflow_env/lib/python3.8/site-packages/dlt/common/configuration/inject.py", line 247, in _wrap
    return f(*bound_args.args, **bound_args.kwargs)
  File "/usr/local/anaconda3/envs/airflow_env/lib/python3.8/site-packages/dlt/pipeline/__init__.py", line 118, in pipeline
    ensure_correct_pipeline_kwargs(pipeline, **injection_kwargs)
  File "/usr/local/anaconda3/envs/airflow_env/lib/python3.8/site-packages/dlt/pipeline/configuration.py", line 58, in ensure_correct_pipeline_kwargs
    raise TypeError(f"{f.__name__} got an unexpected keyword argument '{arg_name}'")
TypeError: pipeline got an unexpected keyword argument 'destination_options'
[2025-03-07T14:06:34.908+0000] {logging_mixin.py:190} INFO - Task instance in failure state
[2025-03-07T14:06:34.908+0000] {logging_mixin.py:190} INFO - Task start:2025-03-07 14:06:34.730044+00:00 end:2025-03-07 14:06:34.907629+00:00 duration:0.177585
[2025-03-07T14:06:34.908+0000] {logging_mixin.py:190} INFO - Task:<Task(PythonOperator): extract_world_bank_data> dag:<DAG: climate_data_dlt_pipeline> dagrun:<DagRun climate_data_dlt_pipeline @ 2025-03-07 14:06:29.267614+00:00: manual__2025-03-07T14:06:29.267614+00:00, state:running, queued_at: 2025-03-07 14:06:29.279567+00:00. externally triggered: True>
[2025-03-07T14:06:34.909+0000] {logging_mixin.py:190} INFO - Failure caused by pipeline got an unexpected keyword argument 'destination_options'
[2025-03-07T14:06:34.909+0000] {taskinstance.py:1226} INFO - Marking task as UP_FOR_RETRY. dag_id=climate_data_dlt_pipeline, task_id=extract_world_bank_data, run_id=manual__2025-03-07T14:06:29.267614+00:00, execution_date=20250307T140629, start_date=20250307T140634, end_date=20250307T140634
[2025-03-07T14:06:34.921+0000] {taskinstance.py:341} INFO - ::group::Post task execution logs
[2025-03-07T14:06:34.921+0000] {standard_task_runner.py:124} ERROR - Failed to execute job 17 for task extract_world_bank_data (pipeline got an unexpected keyword argument 'destination_options'; 7490)
Traceback (most recent call last):
  File "/usr/local/anaconda3/envs/airflow_env/lib/python3.8/site-packages/airflow/task/task_runner/standard_task_runner.py", line 117, in _start_by_fork
    ret = args.func(args, dag=self.dag)
  File "/usr/local/anaconda3/envs/airflow_env/lib/python3.8/site-packages/airflow/cli/cli_config.py", line 49, in command
    return func(*args, **kwargs)
  File "/usr/local/anaconda3/envs/airflow_env/lib/python3.8/site-packages/airflow/utils/cli.py", line 116, in wrapper
    return f(*args, **kwargs)
  File "/usr/local/anaconda3/envs/airflow_env/lib/python3.8/site-packages/airflow/cli/commands/task_command.py", line 483, in task_run
    task_return_code = _run_task_by_selected_method(args, _dag, ti)
  File "/usr/local/anaconda3/envs/airflow_env/lib/python3.8/site-packages/airflow/cli/commands/task_command.py", line 256, in _run_task_by_selected_method
    return _run_raw_task(args, ti)
  File "/usr/local/anaconda3/envs/airflow_env/lib/python3.8/site-packages/airflow/cli/commands/task_command.py", line 341, in _run_raw_task
    return ti._run_raw_task(
  File "/usr/local/anaconda3/envs/airflow_env/lib/python3.8/site-packages/airflow/utils/session.py", line 97, in wrapper
    return func(*args, session=session, **kwargs)
  File "/usr/local/anaconda3/envs/airflow_env/lib/python3.8/site-packages/airflow/models/taskinstance.py", line 3006, in _run_raw_task
    return _run_raw_task(
  File "/usr/local/anaconda3/envs/airflow_env/lib/python3.8/site-packages/airflow/models/taskinstance.py", line 274, in _run_raw_task
    TaskInstance._execute_task_with_callbacks(
  File "/usr/local/anaconda3/envs/airflow_env/lib/python3.8/site-packages/airflow/models/taskinstance.py", line 3161, in _execute_task_with_callbacks
    result = self._execute_task(context, task_orig)
  File "/usr/local/anaconda3/envs/airflow_env/lib/python3.8/site-packages/airflow/models/taskinstance.py", line 3185, in _execute_task
    return _execute_task(self, context, task_orig)
  File "/usr/local/anaconda3/envs/airflow_env/lib/python3.8/site-packages/airflow/models/taskinstance.py", line 768, in _execute_task
    result = _execute_callable(context=context, **execute_callable_kwargs)
  File "/usr/local/anaconda3/envs/airflow_env/lib/python3.8/site-packages/airflow/models/taskinstance.py", line 734, in _execute_callable
    return ExecutionCallableRunner(
  File "/usr/local/anaconda3/envs/airflow_env/lib/python3.8/site-packages/airflow/utils/operator_helpers.py", line 252, in run
    return self.func(*args, **kwargs)
  File "/usr/local/anaconda3/envs/airflow_env/lib/python3.8/site-packages/airflow/models/baseoperator.py", line 424, in wrapper
    return func(self, *args, **kwargs)
  File "/usr/local/anaconda3/envs/airflow_env/lib/python3.8/site-packages/airflow/operators/python.py", line 238, in execute
    return_value = self.execute_callable()
  File "/usr/local/anaconda3/envs/airflow_env/lib/python3.8/site-packages/airflow/operators/python.py", line 256, in execute_callable
    return runner.run(*self.op_args, **self.op_kwargs)
  File "/usr/local/anaconda3/envs/airflow_env/lib/python3.8/site-packages/airflow/utils/operator_helpers.py", line 252, in run
    return self.func(*args, **kwargs)
  File "/Users/gabi/codes/climate_trace/climate_data_pipeline/dags/dlt-airflow-dag.py", line 50, in extract_world_bank_data
    csv_path = run_world_bank_pipeline(year, WORLD_BANK_DIR)
  File "/Users/gabi/codes/climate_trace/climate_data_pipeline/scripts/dlt_extractor.py", line 155, in run_world_bank_pipeline
    pipeline = dlt.pipeline(
  File "/usr/local/anaconda3/envs/airflow_env/lib/python3.8/site-packages/dlt/common/configuration/inject.py", line 247, in _wrap
    return f(*bound_args.args, **bound_args.kwargs)
  File "/usr/local/anaconda3/envs/airflow_env/lib/python3.8/site-packages/dlt/pipeline/__init__.py", line 118, in pipeline
    ensure_correct_pipeline_kwargs(pipeline, **injection_kwargs)
  File "/usr/local/anaconda3/envs/airflow_env/lib/python3.8/site-packages/dlt/pipeline/configuration.py", line 58, in ensure_correct_pipeline_kwargs
    raise TypeError(f"{f.__name__} got an unexpected keyword argument '{arg_name}'")
TypeError: pipeline got an unexpected keyword argument 'destination_options'
[2025-03-07T14:06:34.938+0000] {local_task_job_runner.py:266} INFO - Task exited with return code 1
[2025-03-07T14:06:34.950+0000] {taskinstance.py:3901} INFO - 0 downstream tasks scheduled from follow-on schedule check
[2025-03-07T14:06:34.951+0000] {local_task_job_runner.py:245} INFO - ::endgroup::
