[2025-03-07T15:46:15.626+0100] {local_task_job_runner.py:123} INFO - ::group::Pre task execution logs
[2025-03-07T15:46:15.632+0100] {taskinstance.py:2614} INFO - Dependencies all met for dep_context=non-requeueable deps ti=<TaskInstance: climate_data_pipeline.extract_climate_trace_data manual__2025-03-07T14:45:58.280064+00:00 [queued]>
[2025-03-07T15:46:15.636+0100] {taskinstance.py:2614} INFO - Dependencies all met for dep_context=requeueable deps ti=<TaskInstance: climate_data_pipeline.extract_climate_trace_data manual__2025-03-07T14:45:58.280064+00:00 [queued]>
[2025-03-07T15:46:15.637+0100] {taskinstance.py:2867} INFO - Starting attempt 1 of 2
[2025-03-07T15:46:15.644+0100] {taskinstance.py:2890} INFO - Executing <Task(PythonOperator): extract_climate_trace_data> on 2025-03-07 14:45:58.280064+00:00
[2025-03-07T15:46:15.651+0100] {standard_task_runner.py:72} INFO - Started process 11968 to run task
[2025-03-07T15:46:15.657+0100] {standard_task_runner.py:104} INFO - Running: ['airflow', 'tasks', 'run', 'climate_data_pipeline', 'extract_climate_trace_data', 'manual__2025-03-07T14:45:58.280064+00:00', '--job-id', '34', '--raw', '--subdir', 'DAGS_FOLDER/climate-data-dag.py', '--cfg-path', '/var/folders/55/x1yqz6851xj6j2f0smdhs4jh0000gn/T/tmpx2iverat']
[2025-03-07T15:46:15.659+0100] {standard_task_runner.py:105} INFO - Job 34: Subtask extract_climate_trace_data
[2025-03-07T15:46:15.692+0100] {task_command.py:467} INFO - Running <TaskInstance: climate_data_pipeline.extract_climate_trace_data manual__2025-03-07T14:45:58.280064+00:00 [running]> on host gabis-imac-pro.local
[2025-03-07T15:46:15.735+0100] {taskinstance.py:3134} INFO - Exporting env vars: AIRFLOW_CTX_DAG_OWNER='zoomcamp' AIRFLOW_CTX_DAG_ID='climate_data_pipeline' AIRFLOW_CTX_TASK_ID='extract_climate_trace_data' AIRFLOW_CTX_EXECUTION_DATE='2025-03-07T14:45:58.280064+00:00' AIRFLOW_CTX_TRY_NUMBER='1' AIRFLOW_CTX_DAG_RUN_ID='manual__2025-03-07T14:45:58.280064+00:00'
[2025-03-07T15:46:15.737+0100] {logging_mixin.py:190} INFO - Task instance is in running state
[2025-03-07T15:46:15.737+0100] {logging_mixin.py:190} INFO -  Previous state of the Task instance: queued
[2025-03-07T15:46:15.738+0100] {logging_mixin.py:190} INFO - Current task name:extract_climate_trace_data state:running start_date:2025-03-07 14:46:15.633068+00:00
[2025-03-07T15:46:15.738+0100] {logging_mixin.py:190} INFO - Dag name:climate_data_pipeline and current dag run status:running
[2025-03-07T15:46:15.738+0100] {taskinstance.py:732} INFO - ::endgroup::
[2025-03-07T15:46:15.739+0100] {logging_mixin.py:190} INFO - Fetching list of countries from Climate Trace API
[2025-03-07T15:46:16.012+0100] {logging_mixin.py:190} INFO - Processing batch of 10 countries...
[2025-03-07T15:46:16.013+0100] {taskinstance.py:3313} ERROR - Task failed with exception
Traceback (most recent call last):
  File "/usr/local/anaconda3/envs/airflow_env/lib/python3.8/site-packages/airflow/models/taskinstance.py", line 768, in _execute_task
    result = _execute_callable(context=context, **execute_callable_kwargs)
  File "/usr/local/anaconda3/envs/airflow_env/lib/python3.8/site-packages/airflow/models/taskinstance.py", line 734, in _execute_callable
    return ExecutionCallableRunner(
  File "/usr/local/anaconda3/envs/airflow_env/lib/python3.8/site-packages/airflow/utils/operator_helpers.py", line 252, in run
    return self.func(*args, **kwargs)
  File "/usr/local/anaconda3/envs/airflow_env/lib/python3.8/site-packages/airflow/models/baseoperator.py", line 424, in wrapper
    return func(self, *args, **kwargs)
  File "/usr/local/anaconda3/envs/airflow_env/lib/python3.8/site-packages/airflow/operators/python.py", line 238, in execute
    return_value = self.execute_callable()
  File "/usr/local/anaconda3/envs/airflow_env/lib/python3.8/site-packages/airflow/operators/python.py", line 256, in execute_callable
    return runner.run(*self.op_args, **self.op_kwargs)
  File "/usr/local/anaconda3/envs/airflow_env/lib/python3.8/site-packages/airflow/utils/operator_helpers.py", line 252, in run
    return self.func(*args, **kwargs)
  File "/Users/gabi/codes/climate_trace/climate_data_pipeline/dags/climate-data-dag.py", line 55, in extract_climate_trace_data
    return run_climate_trace_pipeline(year, CLIMATE_TRACE_DIR)
  File "/Users/gabi/codes/climate_trace/climate_data_pipeline/scripts/data_extractor.py", line 151, in run_climate_trace_pipeline
    df = fetch_climate_trace_data(year)
  File "/Users/gabi/codes/climate_trace/climate_data_pipeline/scripts/data_extractor.py", line 96, in fetch_climate_trace_data
    url = f"https://api.climatetrace.org/v6/country/emissions?since={year}&to={year+1}&countries={countries_str}"
TypeError: can only concatenate str (not "int") to str
[2025-03-07T15:46:16.020+0100] {logging_mixin.py:190} INFO - Task instance in failure state
[2025-03-07T15:46:16.020+0100] {logging_mixin.py:190} INFO - Task start:2025-03-07 14:46:15.633068+00:00 end:2025-03-07 14:46:16.020046+00:00 duration:0.386978
[2025-03-07T15:46:16.021+0100] {logging_mixin.py:190} INFO - Task:<Task(PythonOperator): extract_climate_trace_data> dag:<DAG: climate_data_pipeline> dagrun:<DagRun climate_data_pipeline @ 2025-03-07 14:45:58.280064+00:00: manual__2025-03-07T14:45:58.280064+00:00, state:running, queued_at: 2025-03-07 14:45:58.287071+00:00. externally triggered: True>
[2025-03-07T15:46:16.021+0100] {logging_mixin.py:190} INFO - Failure caused by can only concatenate str (not "int") to str
[2025-03-07T15:46:16.022+0100] {taskinstance.py:1226} INFO - Marking task as UP_FOR_RETRY. dag_id=climate_data_pipeline, task_id=extract_climate_trace_data, run_id=manual__2025-03-07T14:45:58.280064+00:00, execution_date=20250307T144558, start_date=20250307T144615, end_date=20250307T144616
[2025-03-07T15:46:16.036+0100] {taskinstance.py:341} INFO - ::group::Post task execution logs
[2025-03-07T15:46:16.037+0100] {standard_task_runner.py:124} ERROR - Failed to execute job 34 for task extract_climate_trace_data (can only concatenate str (not "int") to str; 11968)
Traceback (most recent call last):
  File "/usr/local/anaconda3/envs/airflow_env/lib/python3.8/site-packages/airflow/task/task_runner/standard_task_runner.py", line 117, in _start_by_fork
    ret = args.func(args, dag=self.dag)
  File "/usr/local/anaconda3/envs/airflow_env/lib/python3.8/site-packages/airflow/cli/cli_config.py", line 49, in command
    return func(*args, **kwargs)
  File "/usr/local/anaconda3/envs/airflow_env/lib/python3.8/site-packages/airflow/utils/cli.py", line 116, in wrapper
    return f(*args, **kwargs)
  File "/usr/local/anaconda3/envs/airflow_env/lib/python3.8/site-packages/airflow/cli/commands/task_command.py", line 483, in task_run
    task_return_code = _run_task_by_selected_method(args, _dag, ti)
  File "/usr/local/anaconda3/envs/airflow_env/lib/python3.8/site-packages/airflow/cli/commands/task_command.py", line 256, in _run_task_by_selected_method
    return _run_raw_task(args, ti)
  File "/usr/local/anaconda3/envs/airflow_env/lib/python3.8/site-packages/airflow/cli/commands/task_command.py", line 341, in _run_raw_task
    return ti._run_raw_task(
  File "/usr/local/anaconda3/envs/airflow_env/lib/python3.8/site-packages/airflow/utils/session.py", line 97, in wrapper
    return func(*args, session=session, **kwargs)
  File "/usr/local/anaconda3/envs/airflow_env/lib/python3.8/site-packages/airflow/models/taskinstance.py", line 3006, in _run_raw_task
    return _run_raw_task(
  File "/usr/local/anaconda3/envs/airflow_env/lib/python3.8/site-packages/airflow/models/taskinstance.py", line 274, in _run_raw_task
    TaskInstance._execute_task_with_callbacks(
  File "/usr/local/anaconda3/envs/airflow_env/lib/python3.8/site-packages/airflow/models/taskinstance.py", line 3161, in _execute_task_with_callbacks
    result = self._execute_task(context, task_orig)
  File "/usr/local/anaconda3/envs/airflow_env/lib/python3.8/site-packages/airflow/models/taskinstance.py", line 3185, in _execute_task
    return _execute_task(self, context, task_orig)
  File "/usr/local/anaconda3/envs/airflow_env/lib/python3.8/site-packages/airflow/models/taskinstance.py", line 768, in _execute_task
    result = _execute_callable(context=context, **execute_callable_kwargs)
  File "/usr/local/anaconda3/envs/airflow_env/lib/python3.8/site-packages/airflow/models/taskinstance.py", line 734, in _execute_callable
    return ExecutionCallableRunner(
  File "/usr/local/anaconda3/envs/airflow_env/lib/python3.8/site-packages/airflow/utils/operator_helpers.py", line 252, in run
    return self.func(*args, **kwargs)
  File "/usr/local/anaconda3/envs/airflow_env/lib/python3.8/site-packages/airflow/models/baseoperator.py", line 424, in wrapper
    return func(self, *args, **kwargs)
  File "/usr/local/anaconda3/envs/airflow_env/lib/python3.8/site-packages/airflow/operators/python.py", line 238, in execute
    return_value = self.execute_callable()
  File "/usr/local/anaconda3/envs/airflow_env/lib/python3.8/site-packages/airflow/operators/python.py", line 256, in execute_callable
    return runner.run(*self.op_args, **self.op_kwargs)
  File "/usr/local/anaconda3/envs/airflow_env/lib/python3.8/site-packages/airflow/utils/operator_helpers.py", line 252, in run
    return self.func(*args, **kwargs)
  File "/Users/gabi/codes/climate_trace/climate_data_pipeline/dags/climate-data-dag.py", line 55, in extract_climate_trace_data
    return run_climate_trace_pipeline(year, CLIMATE_TRACE_DIR)
  File "/Users/gabi/codes/climate_trace/climate_data_pipeline/scripts/data_extractor.py", line 151, in run_climate_trace_pipeline
    df = fetch_climate_trace_data(year)
  File "/Users/gabi/codes/climate_trace/climate_data_pipeline/scripts/data_extractor.py", line 96, in fetch_climate_trace_data
    url = f"https://api.climatetrace.org/v6/country/emissions?since={year}&to={year+1}&countries={countries_str}"
TypeError: can only concatenate str (not "int") to str
[2025-03-07T15:46:16.055+0100] {local_task_job_runner.py:266} INFO - Task exited with return code 1
[2025-03-07T15:46:16.070+0100] {taskinstance.py:3901} INFO - 0 downstream tasks scheduled from follow-on schedule check
[2025-03-07T15:46:16.071+0100] {local_task_job_runner.py:245} INFO - ::endgroup::
